Workbook

Sheet SNTDR 2169
A1: FECHA | B1: M | C1: S | D1: C | E1: # | F1: PROVEEDOR | G1: F VTA | H1: RETIRO | I1: DEPOSITO | J1: SALDO
A2: 46024 | B2: G | D2: 612 | F2: EMISION DE CHEQUERA LIBRAMIENTO DE CHEQU | H2: 1460 | J2: 526.71 | K2: =J2+H2-I2 -> 1986.71
A3: 46024 | B3: G | D3: 147 | F3: IVA | H3: 233.6 | J3: =J2-H3+I3 -> 293.11
A4: 46024 | B4: I | C4: 42 | D4: 102 | F4: TARJETALA PIEDAD ABASTOS | G4: 46022 | I4: 3940.04 | J4: =J3-H4+I4 -> 4233.15
A5: 46024 | B5: I | C5: 50 | D5: 102 | F5: VENTAS CANINDO TARJETA | G5: 46022 | I5: 7274.8 | J5: =J4-H5+I5 -> 11507.95
A6: 46024 | B6: I | C6: 10 | D6: 102 | F6: VENTAS PADRE HIDALGO | G6: AA | I6: 11119.7 | J6: =J5-H6+I6 -> 22627.65
A7: 46024 | B7: I | C7: V | D7: 102 | F7: VENTAS PADRE HIDALGO | G7: AA | I7: 3082.59 | J7: =J6-H7+I7 -> 25710.24
A8: 46024 | B8: I | C8: 10 | D8: 102 | F8: VENTAS PADRE HIDALGO | G8: AA | I8: 16282.05 | J8: =J7-H8+I8 -> 41992.29
A9: 46024 | B9: I | C9: 10 | D9: 102 | F9: TARJETA VTA PADRE HIDALGO | G9: 01//01/26 | I9: 9951.69 | J9: =J8-H9+I9 -> 51943.98
A10: 46024 | B10: I | C10: 10 | D10: 102 | F10: VENTAS PADRE HIDALGO | G10: AA | I10: 27173.82 | J10: =J9-H10+I10 -> 79117.8
A11: 46024 | B11: I | C11: 10 | D11: 102 | F11: VENTAS PADRE HIDALGO | G11: AA | I11: 19794.23 | J11: =J10-H11+I11 -> 98912.03
A12: 46024 | B12: I | C12: 50 | D12: 102 | F12: VENTAS CANINDO TARJETA | G12: 46022 | I12: 3115.38 | J12: =J11-H12+I12 -> 102027.41
A13: 46024 | B13: I | C13: 42 | D13: 102 | F13: TARJETALA PIEDAD ABASTOS | I13: 16757.4 | J13: =J12-H13+I13 -> 118784.81
A14: 46024 | B14: G | D14: 612 | F14: Comision | H14: 150 | J14: =J13-H14+I14 -> 118634.81
A15: 46024 | B15: G | D15: 147 | F15: Iva | H15: 24 | J15: =J14-H15+I15 -> 118610.81
A16: 46024 | B16: G | D16: 612 | F16: Comision | H16: 68.86 | J16: =J15-H16+I16 -> 118541.95
A17: 46024 | B17: G | D17: 147 | F17: Iva | H17: 11.02 | J17: =J16-H17+I17 -> 118530.93
A18: 46024 | B18: G | D18: 612 | F18: Comision | H18: 200 | J18: =J17-H18+I18 -> 118330.93
A19: 46024 | B19: G | D19: 147 | F19: Iva | H19: 32 | J19: =J18-H19+I19 -> 118298.93
A20: 46024 | B20: G | D20: 612 | F20: Comision | H20: 137.11 | J20: =J19-H20+I20 -> 118161.82
A21: 46024 | B21: G | D21: 147 | F21: Iva | H21: 21.94 | J21: =J20-H21+I21 -> 118139.88
A22: 46024 | B22: G | D22: 612 | F22: Comision | H22: 200 | J22: =J21-H22+I22 -> 117939.88
A23: 46024 | B23: G | D23: 147 | F23: Iva | H23: 32 | J23: =J22-H23+I23 -> 117907.88
A24: 46024 | B24: G | D24: 612 | F24: Comision | H24: 196.59 | J24: =J23-H24+I24 -> 117711.29
A25: 46024 | B25: G | D25: 147 | F25: Iva | H25: 31.45 | J25: =J24-H25+I25 -> 117679.84
... A45: 46024 | B45: G | D45: 147 | F45: Iva | H45: 32 | J45: =J44-H45+I45 -> 114873.19
A46: 46024 | B46: G | D46: 612 | E46: 1 | F46: Tdc American Express | H46: 9 | J46: =J45-H46+I46 -> 114864.19
A47: 46024 | B47: I | D47: 102 | F47: Dep. Efectivo | I47: 106.5 | J47: =J46-H47+I47 -> 114970.69
A48: 46024 | B48: I | C48: 10 | D48: 102 | F48: VENTAS PADRE HIDALGO | G48: 46023 | I48: 34776 | J48: =J47-H48+I48 -> 149746.69
A49: 46024 | B49: G | C49: 40 | D49: 610 | E49: 2 | F49: Nomina 01 | H49: 35088.8 | J49: =J48-H49+I49 -> 114657.89
A50: 46024 | B50: G | C50: 42 | D50: 610 | E50: 3 | F50: Nomina 01 | H50: 18889.6 | J50: =J49-H50+I50 -> 95768.29
A51: 46024 | B51: I | C51: 10 | D51: 102 | F51: VENTAS PADRE HIDALGO | I51: 225800.5 | J51: =J50-H51+I51 -> 321568.79
A52: 46024 | B52: I | C52: 42 | D52: 102 | F52: VENTAS LA PIEDAD ABASTOS | G52: 46022 | I52: 110943 | J52: =J51-H52+I52 -> 432511.79
A53: 46024 | B53: I | C53: 10 | D53: 102 | F53: VENTAS PADRE HIDALGO | I53: 34651.5 | J53: =J52-H53+I53 -> 467163.29
A54: 46024 | B54: I | C54: 10 | D54: 102 | F54: VENTAS PADRE HIDALGO | I54: 517.5 | J54: =J53-H54+I54 -> 467680.79
A55: 46024 | B55: I | C55: 10 | D55: 102 | F55: VENTAS PADRE HIDALGO | I55: 47 | J55: =J54-H55+I55 -> 467727.79
A56: 46024 | B56: I | C56: 10 | D56: 102 | F56: VENTAS PADRE HIDALGO | I56: 23988 | J56: =J55-H56+I56 -> 491715.79
A57: 46024 | B57: I | C57: 10 | D57: 102 | F57: VENTAS PADRE HIDALGO | I57: 3350 | J57: =J56-H57+I57 -> 495065.79
A58: 46024 | B58: I | C58: 10 | D58: 102 | F58: VENTAS PADRE HIDALGO | I58: 9918 | J58: =J57-H58+I58 -> 504983.79
A59: 46024 | B59: I | C59: 10 | D59: 102 | F59: VENTAS PADRE HIDALGO | I59: 401 | J59: =J58-H59+I59 -> 505384.79
...

Sheet BNMX 1463
A1: FECHA | B1: M | C1: S | D1: C | E1: # | F1: PROVEEDOR | G1: F VTA | H1: RETIRO | I1: DEPOSITO | J1: SALDO
A2: 46028 | B2: I | C2: 70 | D2: 102 | F2: VTA TLMK PH ELIZABETH RUIZ MIRAMONTES | G2: 46007 | I2: 12149.37 | J2: 28921.26 | K2: =J2+H2-I2 -> 16771.89
A3: 46029 | B3: I | C3: N/A | D3: 102 | F3: 3010172 | I3: 0 | J3: =J2-H3+I3 -> 28921.26
A4: 46029 | B4: I | C4: 73 | D4: 102 | F4: Vta.Tlmk Morelia Mariana Jacinto | G4: 46020 | I4: 10452.04 | J4: =J3-H4+I4 -> 39373.3
A5: 46029 | B5: I | C5: N/A | D5: 102 | F5: 3010172 | I5: 0 | J5: =J4-H5+I5 -> 39373.3
A6: 46029 | B6: I | C6: 73 | D6: 102 | F6: Vta.Tlmk Morelia Mariana Jacinto | G6: 45986 | I6: 4480.58 | J6: =J5-H6+I6 -> 43853.88
A7: 46030 | B7: I | C7: 90 | D7: 102 | F7: VTA. YURECUARO | G7: 46028 | I7: 15212 | J7: =J6-H7+I7 -> 59065.88
A8: 46030 | B8: I | C8: 90 | D8: 102 | F8: VTA. YURECUARO | G8: 46027 | I8: 28201 | J8: =J7-H8+I8 -> 87266.88
A9: 46031 | B9: G | C9: 72 | D9: 612 | F9: ADMINISTRACION PAQUETE DE SERVICIOS PYME | H9: 490 | J9: =J8-H9+I9 -> 86776.88
A10: 46031 | B10: G | C10: 72 | D10: 147 | F10: IVA | H10: 78.4 | J10: =J9-H10+I10 -> 86698.48
A11: 46031 | B11: C | D11: 102 | E11: 1 | F11: Dulces Las Delicias Sa de CV | H11: 37285.39 | J11: =J10-H11+I11 -> 49413.09
A12: 46031 | B12: C | D12: 102 | E12: 2 | F12: Dulces Las Delicias Sa de CV | H12: 48740.08 | J12: =J11-H12+I12 -> 673.01
A13: 46034 | B13: I | C13: 70 | D13: 102 | F13: Vta.Tlmk Ph Wendy Maria | G13: 46017 | I13: 7186 | J13: =J12-H13+I13 -> 7859.01
A14: 46034 | B14: I | C14: N/A | D14: 102 | F14: 70880 | I14: 0 | J14: =J13-H14+I14 -> 7859.01
A15: 46037 | B15: I | C15: 70 | D15: 102 | F15: VTA TLMK MORELIA EDUARDO SAMANO SCHUENEMANN | G15: 46005 | I15: 2239.07 | J15: =J14-H15+I15 -> 10098.08
A16: 46038 | B16: I | C16: 70 | D16: 102 | F16: KAREN JANETH AYALA RODRIGUEZ | I16: 1265.43 | J16: =J15-H16+I16 -> 11363.51
A17: 46041 | B17: I | C17: N/A | D17: 102 | F17: 303056 | I17: 0 | J17: =J16-H17+I17 -> 11363.51
A18: 46041 | B18: I | C18: 73 | D18: 102 | F18: Vta.Tlmk Morelia Maria luisa | G18: 46015 | I18: 4037.18 | J18: =J17-H18+I18 -> 15400.69
A19: 46041 | B19: I | C19: N/A | D19: 102 | F19: 303056 | I19: 0 | J19: =J18-H19+I19 -> 15400.69
A20: 46041 | B20: I | C20: 73 | D20: 102 | F20: Vta.Tlmk Morelia Maria Luisa | G20: 46015 | I20: 9339.36 | J20: =J19-H20+I20 -> 24740.05
A21: 46041 | B21: I | C21: 73 | D21: 102 | F21: Vta.Tlmk Morelia Ruben Pantoja | G21: 46024 | I21: 3395.98 | J21: =J20-H21+I21 -> 28136.03
A22: 46043 | B22: I | C22: 70 | D22: 102 | F22: VTA TLMK PH ELIZABETH RUIZ MIRAMONTES | G22: 13/01/2026 Y 06/01/2026 | I22: 2440.11 | J22: =J21-H22+I22 -> 30576.14
A23: 46043 | B23: I | C23: 73 | D23: 102 | F23: Vta.Tlmk Morelia Silvia Mendoza | G23: 46022 | I23: 11970.67 | J23: =J22-H23+I23 -> 42546.81
A24: 46043 | B24: I | C24: 73 | D24: 102 | F24: Vta.Tlmk Morelia Silvia Mendoza | G24: 46030 | I24: 15244.61 | J24: =J23-H24+I24 -> 57791.42
A25: 46043 | B25: I | C25: 73 | D25: 102 | F25: Vta.Tlmk Morelia Silvia Mendoza | G25: 46038 | I25: 9781.57 | J25: =J24-H25+I25 -> 67572.99
A26: 46045 | B26: TE | D26: - | F26: TRASPASO A SNTDRD 2169 | H26: 65000 | J26: =J25-H26+I26 -> 2572.99
A27: 46051 | B27: I | C27: 10 | D27: 102 | F27: SUPER LOS PANCHOS SA DE CV Tlmk Ph | I27: 25443.76 | J27: =J26-H27+I27 -> 28016.75
A28: 46051 | B28: I | C28: 10 | D28: 102 | F28: VIVIANA ITZEL JAIMES MADRIZ | I28: 12470 | J28: =J27-H28+I28 -> 40486.75
A29: 46052 | B29: TE | D29: - | F29: TRASPASO A BTE 7744 | H29: 40000 | J29: =J28-H29+I29 -> 486.75
H31: =SUM(H2:H29) -> 191593.87 | I31: =SUM(I2:I29)+K2 -> 192080.62
I32: =I31-H31 -> 486.75

Sheet BTE 3041
A1: FECHA | B1: M | C1: S | D1: C | E1: # | F1: PROVEEDOR | G1: F VTA | H1: RETIRO | I1: DEPOSITO | J1: SALDO
A2: 46024 | B2: I | C2: 70 | D2: 102 | F2: Vta.Tlmk Ph Andrea Angelica | G2: 45994 | I2: 10000 | J2: 11094.18 | K2: =J2+H2-I2 -> 1094.18
A3: 46027 | B3: I | C3: 70 | D3: 102 | F3: Vta.Tlmk Ph Anahi Elizabeth | G3: 46007 | I3: 7087.01 | J3: =J2+I3-H3 -> 18181.19
A4: 46027 | B4: I | C4: 70 | D4: 102 | F4: Vta.Tlmk Ph Rocio Pimentel | G4: 46009 | I4: 20000 | J4: =J3+I4-H4 -> 38181.19
A5: 46027 | B5: I | C5: 70 | D5: 102 | F5: Vta.Tlmk Ph Cecy Fruta | G5: 46021 | I5: 3920 | J5: =J4+I5-H5 -> 42101.19
A6: 46027 | B6: I | C6: 70 | D6: 102 | F6: Vta.Tlmk Ph Cecy Fruta | G6: 46002 | I6: 1548 | J6: =J5+I6-H6 -> 43649.19
A7: 46027 | B7: I | C7: 70 | D7: 102 | F7: Vta.Tlmk Ph Castillo Uribe | G7: 46021 | I7: 7731 | J7: =J6+I7-H7 -> 51380.19
A8: 46027 | B8: I | C8: 70 | D8: 102 | F8: Vta.Tlmk Ph Ismael Arias | G8: 45993 | I8: 2153 | J8: =J7+I8-H8 -> 53533.19
A9: 46027 | B9: I | C9: 70 | D9: 102 | F9: Vta.Tlmk Ph Adrian Ornelas | G9: 46007 | I9: 9750 | J9: =J8+I9-H9 -> 63283.19
A10: 46027 | B10: I | C10: 70 | D10: 102 | F10: Vta.Tlmk Ph Cueritos Lupita | G10: 45979 | I10: 15000 | J10: =J9+I10-H10 -> 78283.19
A11: 46027 | B11: I | C11: 70 | D11: 102 | F11: Vta.Tlmk Ph Ismael Rodriguez | G11: 46022 | I11: 20311 | J11: =J10+I11-H11 -> 98594.19
A12: 46027 | B12: I | C12: 70 | D12: 102 | F12: Vta.Tlmk Ph Miguel Angel Servin | G12: 46022 | I12: 8811 | J12: =J11+I12-H12 -> 107405.19
A13: 46027 | B13: I | C13: 70 | D13: 102 | F13: Vta.Tlmk Ph Delia Govea | G13: 46022 | I13: 10696 | J13: =J12+I13-H13 -> 118101.19
A14: 46027 | B14: I | C14: 70 | D14: 102 | F14: Vta.Tlmk Ph Rocio Sanchez | G14: 46022 | I14: 334 | J14: =J13+I14-H14 -> 118435.19
... A18: 46027 | B18: I | C18: 70 | D18: 102 | F18: Vta.Tlmk Ph Camarena Jacinto | G18: 46024 | I18: 5643 | J18: =J17+I18-H18 -> 140968.19
A19: 46027 | B19: C | C19: 0 | D19: 510 | E19: 1 | F19: Comercializadora Gonac SA de CV | H19: 120323.17 | J19: =J18+I19-H19 -> 20645.02
A20: 46027 | B20: C | C20: 10 | D20: 510 | E20: 2 | F20: Abarrotes del Centro Guerrero | H20: 13065.01 | J20: =J19+I20-H20 -> 7580.01
A21: 46029 | B21: I | C21: 70 | D21: 102 | F21: Vta.Tlmk Ph Gutierrez Lara | G21: 46014 | I21: 21572 | J21: =J20+I21-H21 -> 29152.01
A22: 46029 | B22: I | C22: 70 | D22: 102 | F22: Vta.Tlmk Ph Andrea Angelica | G22: 45994 | I22: 10000 | J22: =J21+I22-H22 -> 39152.01
A23: 46029 | B23: I | C23: 70 | D23: 102 | F23: Vta.Tlmk Ph Carniceria Duran | G23: 46003 | I23: 300 | J23: =J22+I23-H23 -> 39452.01
A24: 46029 | B24: I | C24: 70 | D24: 102 | F24: Vta.Tlmk Ph Luis Felipe torres | G24: 46020 | I24: 1145 | J24: =J23+I24-H24 -> 40597.01
A25: 46029 | B25: I | C25: 70 | D25: 102 | F25: Vta.Tlmk Ph Gastos Tlmk | G25: 46029 | I25: 204 | J25: =J24+I25-H25 -> 40801.01
A26: 46029 | B26: I | C26: 70 | D26: 102 | F26: Vta.Tlmk Ph Lourdes Encino | G26: 45992 | I26: 14783.44 | J26: =J25+I26-H26 -> 55584.45
A27: 46029 | B27: I | C27: 70 | D27: 102 | F27: Vta.Tlmk Ph Lourdes Encino | G27: 45985 | I27: 16918.7 | J27: =J26+I27-H27 -> 72503.15
A28: 46029 | B28: I | C28: 70 | D28: 102 | F28: Vta.Tlmk Ph Ma. Lourdes Encino | G28: 46027 | I28: 1010.19 | J28: =J27+I28-H28 -> 73513.34
A29: 46029 | B29: I | C29: 70 | D29: 102 | F29: Vta.Tlmk Ph Ma. Lourdes Encino | G29: 46027 | I29: 1498.76 | J29: =J28+I29-H29 -> 75012.1
A30: 46029 | B30: I | C30: 70 | D30: 102 | F30: Vta.Tlmk Ph Ma. Lourdes Encino | G30: 46027 | I30: 1864.08 | J30: =J29+I30-H30 -> 76876.18
A31: 46029 | B31: i | C31: 70 | D31: 102 | F31: Vta.Tlmk Ph Lourdes Encino | G31: 45996 | I31: 4521 | J31: =J30+I31-H31 -> 81397.18
A32: 46029 | B32: I | C32: 70 | D32: 102 | F32: Vta.Tlmk Ph Lourdes Encino | G32: 45996 | I32: 17334.25 | J32: =J31+I32-H32 -> 98731.43
... A45: 46029 | B45: I | C45: 70 | D45: 102 | F45: Vta.Tlmk Ph Sergio Ochoa | G45: 46027 | I45: 3470 | J45: =J44+I45-H45 -> 204714.01
A46: 46029 | B46: C | C46: 50 | D46: 510 | E46: 3 | F46: Salsas Don Vasco | H46: 9891.4 | J46: =J45+I46-H46 -> 194822.61
A47: 46029 | B47: C | C47: 30 | D47: 510 | E47: 4 | F47: Salsas Don Vasco | H47: 88922.85 | J47: =J46+I47-H47 -> 105899.76
A48: 46029 | B48: TE | D48: - | F48: TRASPASO A BBVA 5712 | H48: 100000 | J48: =J47+I48-H48 -> 5899.76
A49: 46030 | B49: I | C49: 70 | D49: 102 | F49: Vta.Tlmk Ph Margarita Sanchez | G49: 46000 | I49: 8691 | J49: =J48+I49-H49 -> 14590.76
A50: 46030 | B50: I | C50: 70 | D50: 102 | F50: Vta.Tlmk Ph Ma. Trinidad Vargas | G50: 46014 | I50: 3410 | J50: =J49+I50-H50 -> 18000.76
A51: 46030 | B51: I | C51: 70 | D51: 102 | F51: Vta.Tlmk Ph Margarita Rodriguez | G51: 46028 | I51: 665 | J51: =J50+I51-H51 -> 18665.76
A52: 46030 | B52: I | C52: 70 | D52: 102 | F52: Vta.Tlmk Ph Heriberto Andrade | G52: 6/1//2026 | I52: 1438 | J52: =J51+I52-H52 -> 20103.76
A53: 46030 | B53: I | C53: 70 | D53: 102 | F53: Vta.Tlmk Ph Ismael Arias | G53: 46007 | I53: 4677 | J53: =J52+I53-H53 -> 24780.76
A54: 46030 | B54: I | C54: 70 | D54: 102 | F54: Vta.Tlmk Ph Armando Rea | G54: 46001 | I54: 19000 | J54: =J53+I54-H54 -> 43780.76
A55: 46030 | B55: I | C55: 70 | D55: 102 | F55: Vta.Tlmk Ph Farfan Vazquez | G55: 45988 | I55: 61350 | J55: =J54+I55-H55 -> 105130.76
...

Sheet BB 3660
A1: FECHA | B1: M | C1: S | D1: C | E1: # | F1: PROVEEDOR | G1: F VTA | H1: RETIRO | I1: DEPOSITO | J1: SALDO
A2: 46024 | B2: I | C2: 75 | D2: 102 | F2: Vta.Tlmk Canindo Teresa Manzo | G2: 258/11/2025 | I2: 36569.5 | J2: 37708.16 | K2: =J2+H2-I2 -> 1138.66
A3: 46024 | B3: TE | D3: - | F3: TRASPASO ENTRE CTAS 4166 | H3: 35000 | J3: =J2-H3+I3 -> 2708.16
A4: 46028 | B4: I | C4: 75 | D4: 102 | F4: VTA. TLMKT CANINDO JORGE ALBERTO MANZO | G4: 46025 | I4: 814.92 | J4: =J3-H4+I4 -> 3523.08
A5: 46028 | B5: I | C5: 75 | D5: 102 | F5: Vta.Tlmk Canindo Luis Ibarra | G5: 45989 | I5: 11497 | J5: =J4-H5+I5 -> 15020.08
A6: 46028 | B6: I | C6: 75 | D6: 102 | F6: Vta.Tlmk Canindo Cristina Noeli | G6: 46001 | I6: 21770 | J6: =J5-H6+I6 -> 36790.08
A7: 46028 | B7: I | C7: 75 | D7: 102 | F7: Vta.Tlmk Canindo Claudia Pantoja | G7: 45988 | I7: 9193 | J7: =J6-H7+I7 -> 45983.08
A8: 46028 | B8: I | C8: 75 | D8: 102 | F8: Vta.Tlmk Canindo Virginia Amezcua | G8: 46011 | I8: 16582 | J8: =J7-H8+I8 -> 62565.08
A9: 46028 | B9: I | C9: 75 | D9: 102 | F9: Vta.Tlmk Canindo Nicolas Morillon | G9: 45992 | I9: 22200 | J9: =J8-H9+I9 -> 84765.08
A10: 46028 | B10: I | C10: 75 | D10: 102 | F10: Vta.Tlmk Canindo Francisco Orozco | G10: 45962 | I10: 36600 | J10: =J9-H10+I10 -> 121365.08
A11: 46028 | B11: I | C11: 75 | D11: 102 | F11: Vta.Tlmk Canindo Alexis Amezcua | G11: 46001 | I11: 5862 | J11: =J10-H11+I11 -> 127227.08
A12: 46028 | B12: I | C12: 75 | D12: 102 | F12: Vta.Tlmk Canindo Beatriz guadalupe | G12: 46011 | I12: 8500 | J12: =J11-H12+I12 -> 135727.08
A13: 46028 | B13: I | C13: 75 | D13: 102 | F13: Vta.Tlmk Canindo Aurora Rios | G13: 45972 | I13: 34686 | J13: =J12-H13+I13 -> 170413.08
A14: 46028 | B14: I | C14: 75 | D14: 102 | F14: Vta.Tlmk Canindo Rafael Lopez | G14: 46001 | I14: 9129 | J14: =J13-H14+I14 -> 179542.08
A15: 46028 | B15: I | C15: 75 | D15: 102 | F15: VTA TLMKT CANINDO JAIME RAMIREZ | G15: 46027 | I15: 13236 | J15: =J14-H15+I15 -> 192778.08
A16: 46028 | B16: I | C16: 75 | D16: 102 | F16: VTA TLMKT CANINDO JUAN CARLOS DELGADO | G16: 05-01--26 | I16: 10429 | J16: =J15-H16+I16 -> 203207.08
A17: 46028 | B17: I | C17: 75 | D17: 102 | F17: VTA TLMKT CANINDO TANARI CERNA | G17: 46027 | I17: 2475 | J17: =J16-H17+I17 -> 205682.08
A18: 46028 | B18: TE | D18: - | F18: TRASPASO ENTRE CTAS 4166 | H18: 205000 | J18: =J17-H18+I18 -> 682.08
A19: 46030 | B19: I | C19: 75 | D19: 102 | F19: VTA. TLMKT CANINDO FELIPE DE JESUS GALVEZ | G19: 46028 | I19: 151870 | J19: =J18-H19+I19 -> 152552.08
A20: 46030 | B20: I | C20: 75 | D20: 102 | F20: VTA. TLMKT CANINDO J. GUADALUPE TORRES | G20: 46028 | I20: 4248 | J20: =J19-H20+I20 -> 156800.08
A21: 46030 | B21: I | C21: 75 | D21: 102 | F21: VTA. TLMKT CANINDO JAIME EDUARDO M. | G21: 46028 | I21: 4802.77 | J21: =J20-H21+I21 -> 161602.85
A22: 46030 | B22: I | C22: 75 | D22: 102 | F22: VTA TLMKT CANINDO JORGE ALBERTO MANZO | G22: 46029 | I22: 34862 | J22: =J21-H22+I22 -> 196464.85
A23: 46030 | B23: TE | D23: - | F23: TRASPASO ENTRE CTAS 854 | H23: 195000 | J23: =J22-H23+I23 -> 1464.85
A24: 46031 | B24: I | C24: 75 | D24: 102 | F24: VTA TLMKT CANINDO | G24: 46030 | I24: 11097 | J24: =J23-H24+I24 -> 12561.85
A25: 46032 | B25: I | C25: 70 | D25: 102 | F25: Vta.Tlmk Ph Fredy Arroyo | G25: 46020 | I25: 4384.64 | J25: =J24-H25+I25 -> 16946.49
A26: 46034 | B26: I | C26: 75 | D26: 102 | F26: VTA TLMKT CANINDO GERARDO DANIEL A. | G26: 46032 | I26: 8084 | J26: =J25-H26+I26 -> 25030.49
A27: 46034 | B27: I | C27: 75 | D27: 102 | F27: VTA TLMKT CANINDO MARIA GUADAUPE A. | G27: 46031 | I27: 1121 | J27: =J26-H27+I27 -> 26151.49
A28: 46034 | B28: I | C28: 75 | D28: 102 | F28: VTA TLMKT CANINDO LEONARDO IBARRA | G28: 46031 | I28: 14415 | J28: =J27-H28+I28 -> 40566.49
A29: 46034 | B29: I | C29: 75 | D29: 102 | F29: VTA TLMTK CANINDO OCTAVIO MORALES | G29: 46031 | I29: 10778.5 | J29: =J28-H29+I29 -> 51344.99
A30: 46034 | B30: TE | D30: - | F30: TRSAPASO ENTRE CTAS 854 | H30: 30000 | J30: =J29-H30+I30 -> 21344.99
A31: 46035 | B31: I | C31: 75 | D31: 102 | F31: Vta.Tlmk Canindo Luis Ibarra | G31: 46011 | I31: 46260 | J31: =J30-H31+I31 -> 67604.99
A32: 46035 | B32: I | C32: 75 | D32: 102 | F32: Vta.Tlmk Canindo Virginia Amezcua | G32: 46011 | I32: 18000 | J32: =J31-H32+I32 -> 85604.99
A33: 46035 | B33: I | C33: 75 | D33: 102 | F33: Vta.Tlmk Canindo Octaviano Morales | G33: 46011 | I33: 54308 | J33: =J32-H33+I33 -> 139912.99
A34: 46035 | B34: I | C34: 75 | D34: 102 | F34: Vta.Tlmk Canindo Beatriz guadalupe | G34: 46018 | I34: 6450 | J34: =J33-H34+I34 -> 146362.99
A35: 46035 | B35: I | C35: 75 | D35: 102 | F35: Vta.Tlmk Canindo Alberto Perez | G35: 46018 | I35: 3196 | J35: =J34-H35+I35 -> 149558.99
A36: 46035 | B36: I | C36: 75 | D36: 102 | F36: Vta.Tlmk Canindo Fernando Alberto | G36: 46008 | I36: 92005 | J36: =J35-H36+I36 -> 241563.99
A37: 46035 | B37: I | C37: 75 | D37: 102 | F37: Vta.Tlmk Canindo Nicolas Morillon | G37: 46001 | I37: 37915 | J37: =J36-H37+I37 -> 279478.99
A38: 46035 | B38: I | C38: 75 | D38: 102 | F38: Vta.Tlmk Canindo Guadalupe Torres | G38: 45964 | I38: 12500 | J38: =J37-H38+I38 -> 291978.99
A39: 46035 | B39: I | C39: 75 | D39: 102 | F39: Vta.Tlmk Canindo Guadalupe Torres | G39: 45964 | I39: 17500 | J39: =J38-H39+I39 -> 309478.99
A40: 46035 | B40: I | C40: 75 | D40: 102 | F40: Vta.Tlmk Canindo Francisco Orozco | G40: 45978 | I40: 24650 | J40: =J39-H40+I40 -> 334128.99
...

Sheet BTE 7744
A1: FECHA | B1: M | C1: S | D1: C | E1: # | F1: PROVEEDOR | G1: F VTA | H1: RETIRO | I1: DEPOSITO | J1: SALDO
A2: 46024 | B2: I | C2: 30 | D2: 102 | F2: VENTAS MORELIA ABASTOS | G2: 46022 | I2: 11747.49 | J2: 45451.75 | K2: =J2+H2-I2 -> 33704.26
A3: 46024 | B3: G | C3: 30 | D3: 612 | F3: Comision | H3: 88.09 | J3: =J2-H3+I3 -> 45363.66
A4: 46024 | B4: G | C4: 30 | D4: 147 | F4: Iva | H4: 14.11 | J4: =J3-H4+I4 -> 45349.55
A5: 46024 | B5: I | C5: 30 | D5: 102 | F5: VENTAS MORELIA ABASTOS | G5: 46022 | I5: 18847.82 | J5: =J4-H5+I5 -> 64197.37
A6: 46024 | B6: G | C6: 30 | D6: 612 | F6: Comision | H6: 141.32 | J6: =J5-H6+I6 -> 64056.05
A7: 46024 | B7: G | C7: 30 | D7: 147 | F7: Iva | H7: 22.63 | J7: =J6-H7+I7 -> 64033.42
A8: 46024 | B8: I | C8: 10 | D8: 102 | F8: VENTAS PADRE HIDALGO | I8: 290.85 | J8: =J7-H8+I8 -> 64324.27
A9: 46024 | B9: G | D9: 612 | F9: Comision | H9: 9.92 | J9: =J8-H9+I9 -> 64314.35
A10: 46024 | B10: G | D10: 147 | F10: Iva | H10: 1.59 | J10: =J9-H10+I10 -> 64312.76
A11: 46024 | B11: I | C11: 10 | D11: 102 | F11: VENTAS PADRE HIDALGO | I11: 412.54 | J11: =J10-H11+I11 -> 64725.3
A12: 46024 | B12: G | D12: 612 | F12: Comision | H12: 3.1 | J12: =J11-H12+I12 -> 64722.2
A13: 46024 | B13: G | D13: 147 | F13: Iva | H13: 0.5 | J13: =J12-H13+I13 -> 64721.7
A14: 46024 | B14: TI | D14: - | F14: TRASPASO ENTRE CTAS 7133 | I14: 200000 | J14: =J13-H14+I14 -> 264721.7
A15: 46024 | B15: I | D15: 102 | F15: Dep. Practicaja | I15: 215700 | J15: =J14-H15+I15 -> 480421.7
A16: 46024 | B16: TI | D16: - | F16: TRASPASO DE BB 4166 | I16: 100000 | J16: =J15-H16+I16 -> 580421.7
A17: 46024 | B17: G | D17: 610 | E17: 1 | F17: Nomina 01 | H17: 29045 | J17: =J16-H17+I17 -> 551376.7
A18: 46024 | B18: G | C18: 90 | D18: 610 | E18: 2 | F18: Nomina 01 | H18: 8221.4 | J18: =J17-H18+I18 -> 543155.3
A19: 46024 | B19: G | D19: 610 | E19: 3 | F19: Nomina 01 | H19: 1717.6 | J19: =J18-H19+I19 -> 541437.7
A20: 46024 | B20: G | C20: 10 | D20: 610 | E20: 4 | F20: Nomina 01 | H20: 65098.2 | J20: =J19-H20+I20 -> 476339.5
A21: 46024 | B21: G | C21: 20 | D21: 610 | E21: 5 | F21: Nomina 01 | H21: 28296.2 | J21: =J20-H21+I21 -> 448043.3
A22: 46024 | B22: G | C22: 0 | D22: 610 | E22: 6 | F22: Nomina 01 | H22: 43745.2 | J22: =J21-H22+I22 -> 404298.1
A23: 46024 | B23: G | C23: 50 | D23: 610 | E23: 7 | F23: Nomina 01 | H23: 55317.8 | J23: =J22-H23+I23 -> 348980.3
A24: 46024 | B24: G | C24: 54 | D24: 610 | E24: 8 | F24: Nomina 01 | H24: 10742.8 | J24: =J23-H24+I24 -> 338237.5
A25: 46024 | B25: G | C25: 30 | D25: 610 | E25: 9 | F25: Nomina 01 | H25: 68393.2 | J25: =J24-H25+I25 -> 269844.3
A26: 46024 | B26: G | C26: 32 | D26: 610 | E26: 10 | F26: Nomina 01 | H26: 31170.8 | J26: =J25-H26+I26 -> 238673.5
A27: 46024 | B27: C | C27: 50 | D27: 510 | E27: 11 | F27: Distribuidora de la Rosa | H27: 227932.43 | J27: =J26-H27+I27 -> 10741.07
A28: 46024 | B28: I | C28: 70 | D28: 102 | F28: VTA TLMK PH COMERCIALIZADORA LORO LORA | G28: 46024 | I28: 2547.08 | J28: =J27-H28+I28 -> 13288.15
A29: 46024 | B29: G | C29: 72 | D29: 612 | F29: SEGUROS BANORTE SA DE CV GRUPO FINANCIERA CARGO COBRANZA DOMICILIADA | H29: 3790 | J29: =J28-H29+I29 -> 9498.15
A30: 46025 | B30: I | C30: 10 | D30: 102 | F30: VENTAS PADRE HIDALGO | I30: 202840 | J30: =J29-H30+I30 -> 212338.15
A31: 46027 | B31: I | C31: 90 | D31: 102 | F31: VTA. YURECUARO | G31: 46024 | I31: 263.2 | J31: =J30-H31+I31 -> 212601.35
A32: 46027 | B32: G | D32: 612 | F32: Comision | H32: 1.97 | J32: =J31-H32+I32 -> 212599.38
A33: 46027 | B33: G | D33: 147 | F33: Iva | H33: 0.32 | J33: =J32-H33+I33 -> 212599.06
A34: 46027 | B34: I | C34: 30 | D34: 102 | F34: VENTAS MORELIA ABASTOS | G34: 02 Y 03/01/2025 | I34: 6917.64 | J34: =J33-H34+I34 -> 219516.7
A35: 46027 | B35: G | C35: 30 | D35: 612 | F35: Comision | H35: 51.89 | J35: =J34-H35+I35 -> 219464.81
A36: 46027 | B36: G | C36: 30 | D36: 147 | F36: Iva | H36: 8.31 | J36: =J35-H36+I36 -> 219456.5
A37: 46027 | B37: I | C37: 30 | D37: 102 | F37: VENTAS MORELIA ABASTOS | G37: 02 Y 03/01/2025 | I37: 35172.81 | J37: =J36-H37+I37 -> 254629.31
A38: 46027 | B38: G | C38: 30 | D38: 612 | F38: Comision | H38: 296.94 | J38: =J37-H38+I38 -> 254332.37
A39: 46027 | B39: G | C39: 30 | D39: 147 | F39: Iva | H39: 47.53 | J39: =J38-H39+I39 -> 254284.84
A40: 46027 | B40: I | C40: 10 | D40: 102 | F40: VTA PADRE HIDALGO | G40: 46025 | I40: 106620 | J40: =J39-H40+I40 -> 360904.84
...

Sheet BTE 7133
A1: FECHA | B1: M | C1: S | D1: C | E1: # | F1: PROVEEDOR | G1: F VTA | H1: RETIRO | I1: DEPOSITO | J1: SALDO
A2: 46024 | B2: I | C2: 50 | D2: 102 | F2: VENTAS CANINDO | G2: 46021 | I2: 70000 | J2: 73606.31 | K2: =J2+H2-I2 -> 3606.31
A3: 46024 | B3: I | C3: 50 | D3: 102 | F3: VENTAS CANINDO | G3: 46021 | I3: 790 | J3: =J2-H3+I3 -> 74396.31
A4: 46024 | B4: I | C4: 50 | D4: 102 | F4: VENTAS CANINDO | G4: 46022 | I4: 125790 | J4: =J3-H4+I4 -> 200186.31
A5: 46024 | B5: TE | D5: - | F5: TRASPASO ENTRE CTAS 7744 | H5: 200000 | J5: =J4-H5+I5 -> 186.31
A6: 46024 | B6: I | C6: 75 | D6: 102 | F6: Vta.Tlmk Canindo Super Abarrotes | G6: 46021 | I6: 14682.04 | J6: =J5-H6+I6 -> 14868.35
A7: 46024 | B7: I | C7: 75 | D7: 102 | F7: Vta.Tlmk Canindo Super Abarrotes | G7: 46021 | I7: 2626.16 | J7: =J6-H7+I7 -> 17494.51
A8: 46025 | B8: I | C8: 50 | D8: 102 | F8: VENTAS CANINDO | G8: 46022 | I8: 82600 | J8: =J7-H8+I8 -> 100094.51
A9: 46025 | B9: I | C9: 50 | D9: 102 | F9: VENTAS CANINDO | G9: 46024 | I9: 125690 | J9: =J8-H9+I9 -> 225784.51
A10: 46025 | B10: I | C10: 50 | D10: 102 | F10: VENTAS CANINDO | G10: 46024 | I10: 1050 | J10: =J9-H10+I10 -> 226834.51
A11: 46025 | B11: I | C11: 50 | D11: 102 | F11: VENTAS CANINDO | G11: 46024 | I11: 5310 | J11: =J10-H11+I11 -> 232144.51
A12: 46025 | B12: I | C12: 50 | D12: 102 | F12: VENTAS CANINDO | G12: 46024 | I12: 35000 | J12: =J11-H12+I12 -> 267144.51
A13: 46025 | B13: I | C13: 50 | D13: 102 | F13: VENTAS CANINDO | G13: 46024 | I13: 80330 | J13: =J12-H13+I13 -> 347474.51
A14: 46027 | B14: I | C14: 73 | D14: 102 | F14: VENTAS TLMKT MORELIA | I14: 172800 | J14: =J13-H14+I14 -> 520274.51
A15: 46027 | B15: I | C15: 50 | D15: 102 | F15: VENTAS CANINDO | G15: 46026 | I15: 36150 | J15: =J14-H15+I15 -> 556424.51
A16: 46027 | B16: TI | D16: - | F16: TRASPASO ENTRE CTAS 7744 | I16: 90000 | J16: =J15-H16+I16 -> 646424.51
A17: 46027 | B17: C | C17: 10 | D17: 510 | E17: 1 | F17: Distribuidora de la Rosa | H17: 640408.42 | J17: =J16-H17+I17 -> 6016.09
A18: 46028 | B18: I | C18: 50 | D18: 102 | F18: VENTAS CANINDO | G18: 46026 | I18: 25560 | J18: =J17-H18+I18 -> 31576.09
A19: 46028 | B19: I | C19: 50 | D19: 102 | F19: VENTAS CANINDO | G19: 46027 | I19: 295520 | J19: =J18-H19+I19 -> 327096.09
A20: 46028 | B20: I | C20: 50 | D20: 102 | F20: VENTAS CANINDO | G20: 46026 | I20: 3234 | J20: =J19-H20+I20 -> 330330.09
A21: 46028 | B21: I | C21: 50 | D21: 102 | F21: VENTAS CANINDO | G21: 46027 | I21: 5020 | J21: =J20-H21+I21 -> 335350.09
A22: 46028 | B22: I | C22: 75 | D22: 102 | F22: Vta.Tlmk Canindo Maria Leonidez | G22: 46021 | I22: 68172.18 | J22: =J21-H22+I22 -> 403522.27
A23: 46028 | B23: TE | D23: - | F23: TRASPASO ENTRE CTAS 7744 | H23: 400000 | J23: =J22-H23+I23 -> 3522.27
A24: 46029 | B24: I | C24: 50 | D24: 102 | F24: VENTAS CANINDO | G24: 46027 | I24: 26250 | J24: =J23-H24+I24 -> 29772.27
A25: 46029 | B25: I | C25: 50 | D25: 102 | F25: VENTAS CANINDO | G25: 46028 | I25: 71500 | J25: =J24-H25+I25 -> 101272.27
A26: 46029 | B26: I | C26: 50 | D26: 102 | F26: VENTAS CANINDO | G26: 46028 | I26: 81300 | J26: =J25-H26+I26 -> 182572.27 | M26: .
A27: 46029 | B27: I | C27: 50 | D27: 102 | F27: VENTAS CANINDO | G27: 46028 | I27: 37330 | J27: =J26-H27+I27 -> 219902.27
A28: 46029 | B28: I | C28: 75 | D28: 102 | F28: Vta.Tlmk Canindo Guadalupe Torres | G28: 45957 | I28: 42886 | J28: =J27-H28+I28 -> 262788.27
A29: 46029 | B29: I | C29: 75 | D29: 102 | F29: Vta.Tlmk Canindo Guadalupe Torres | G29: 45950 | I29: 38000 | J29: =J28-H29+I29 -> 300788.27
A30: 46029 | B30: G | C30: 71 | D30: 613 | E30: 2 | F30: TDC BANORTE -ML | H30: 1165.14 | J30: =J29-H30+I30 -> 299623.13
A31: 46029 | B31: G | C31: 72 | D31: 610 | E31: 3 | F31: TDC BANORTE -SEGUROS BANORTE | H31: 189 | J31: =J30-H31+I31 -> 299434.13
A32: 46029 | B32: C | D32: 510 | E32: 4 | F32: TDC BANORTE - ABARROTES EL ZORRO | H32: 56486.55 | J32: =J31-H32+I32 -> 242947.58
A33: 46029 | B33: G | C33: 54 | D33: 613 | E33: 5 | F33: TDC BANORTE -BARRADAS | H33: 14876.025 | J33: =J32-H33+I33 -> 228071.55
A34: 46029 | B34: TE | D34: - | F34: TRASPASO A BBVA 5712 | H34: 225000 | J34: =J33-H34+I34 -> 3071.555
A35: 46030 | B35: I | C35: 50 | D35: 102 | F35: VENTAS CANINDO | G35: 46028 | I35: 27120 | J35: =J34-H35+I35 -> 30191.555
A36: 46030 | B36: I | C36: 50 | D36: 102 | F36: VENTAS CANINDO | G36: 46029 | I36: 153550 | J36: =J35-H36+I36 -> 183741.55
A37: 46030 | B37: I | C37: 50 | D37: 102 | F37: VENTAS CANINDO | G37: 46028 | I37: 3811.5 | J37: =J36-H37+I37 -> 187553.05
A38: 46030 | B38: I | C38: 75 | D38: 102 | F38: Vta.Tlmk Canindo Francisco Hernandez | G38: 45975 | I38: 48000 | J38: =J37-H38+I38 -> 235553.05
A39: 46030 | B39: I | C39: 75 | D39: 102 | F39: Vta.Tlmk Canindo Arturo Reynoso | G39: 46015 | I39: 49080 | J39: =J38-H39+I39 -> 284633.05
A40: 46030 | B40: I | C40: 75 | D40: 102 | F40: Vta.Tlmk Canindo Super Abarrotes | G40: 46028 | I40: 2796.61 | J40: =J39-H40+I40 -> 287429.66
...

Sheet BBVA 5712
A1: FECHA | B1: M | C1: S | D1: C | E1: # | F1: PROVEEDOR | G1: F VTA | H1: RETIRO | I1: DEPOSITO | J1: SALDO
A2: 46024 | B2: G | C2: 12 | D2: 613 | E2: 1 | F2: Toyocamiones SA de Cv | H2: 19400 | J2: 17877.06 | K2: =J2+H2-I2 -> 37277.06
A3: 46024 | B3: I | C3: 10 | D3: 102 | F3: VENTA PADRE HIDALGO | G3: 46024 | I3: 6719.65 | J3: =J2-H3+I3 -> 24596.71
A4: 46024 | B4: I | C4: 73 | D4: 102 | F4: Vta.Tlmk Morelia Bernaldo Garcia | G4: 46011 | I4: 3350 | J4: =J3-H4+I4 -> 27946.71
A5: 46024 | B5: I | C5: 10 | D5: 102 | F5: VENTA PADRE HIDALGO | G5: 46024 | I5: 6677.85 | J5: =J4-H5+I5 -> 34624.56
A6: 46024 | B6: C | C6: 50 | D6: 510 | E6: 2 | F6: Jose Alfonso Gonzalez | H6: 4557.6 | J6: =J5-H6+I6 -> 30066.96
A7: 46024 | B7: G | C7: 10 | D7: 610 | E7: 3 | F7: CFE | H7: 16551 | J7: =J6-H7+I7 -> 13515.96
A8: 46027 | B8: I | C8: 73 | D8: 102 | F8: Vta.Tlmk Morelia Leonila Ledezma | G8: 46021 | I8: 2639.39 | J8: =J7-H8+I8 -> 16155.35
A9: 46027 | B9: I | C9: 10 | D9: 102 | F9: VENTA PADRE HIDALGO | G9: 46027 | I9: 870 | J9: =J8-H9+I9 -> 17025.35
A10: 46027 | B10: I | C10: 10 | D10: 102 | F10: VENTA PADRE HIDALGO | G10: 46027 | I10: 870 | J10: =J9-H10+I10 -> 17895.35
A11: 46027 | B11: I | C11: 30 | D11: 102 | F11: VENTAS MORELIA ABASTOS Tlmk M | G11: 45662 | I11: 4418.23 | J11: =J10-H11+I11 -> 22313.58
A12: 46027 | B12: S | C12: 54 | D12: 102 | F12: VENTA ZAMORA CENTRO | I12: 4640 | J12: =J11-H12+I12 -> 26953.58 | L12: devolucion lilia edith
A13: 46027 | B13: I | C13: 40 | D13: 102 | F13: vtas 8 esquinas | G13: 46027 | I13: 1102 | J13: =J12-H13+I13 -> 28055.58
A14: 46027 | B14: TI | D14: - | F14: TRASPASO DE STDR | I14: 700000 | J14: =J13-H14+I14 -> 728055.58
A15: 46027 | B15: TI | D15: - | F15: TRASPASO DE STDR | I15: 150000 | J15: =J14-H15+I15 -> 878055.58
A16: 46027 | B16: C | C16: 30 | D16: 510 | E16: 4 | F16: Alcaruzz S de RL de CV | H16: 89002.58 | J16: =J15-H16+I16 -> 789053
A17: 46027 | B17: C | C17: 50 | D17: 510 | E17: 5 | F17: Alcaruzz S de RL de CV | H17: 22951.64 | J17: =J16-H17+I17 -> 766101.36
A18: 46027 | B18: C | C18: 10 | D18: 510 | E18: 6 | F18: Alcaruzz S de RL de CV | H18: 16978.2 | J18: =J17-H18+I18 -> 749123.16
A19: 46027 | B19: C | C19: 0 | D19: 510 | E19: 7 | F19: Azteca Confiteria | H19: 39972.53 | J19: =J18-H19+I19 -> 709150.63
A20: 46027 | B20: C | C20: 30 | D20: 510 | E20: 8 | F20: Comercializadora Galfra | H20: 37598.04 | J20: =J19-H20+I20 -> 671552.59
A21: 46027 | B21: C | C21: 0 | D21: 510 | E21: 9 | F21: Conservas La Costeña | H21: 308816.73 | J21: =J20-H21+I21 -> 362735.86
A22: 46027 | B22: C | C22: 0 | D22: 510 | E22: 10 | F22: Brenda Jaqueline Avila | H22: 64037.79 | J22: =J21-H22+I22 -> 298698.07
A23: 46027 | B23: G | C23: 1 | D23: 613 | E23: 11 | F23: Gustavo Rodriguez Ramirez | H23: 134649.93 | J23: =J22-H23+I23 -> 164048.14
A24: 46027 | B24: G | C24: 72 | D24: 612 | F24: STM FINANCIAL S.A.P.13663/FFS1512071T1 | H24: 27072.95 | J24: =J23-H24+I24 -> 136975.19
A25: 46028 | B25: I | C25: 90 | D25: 102 | F25: VTA. YURECUARO | G25: 46024 | I25: 28070 | J25: =J24-H25+I25 -> 165045.19
A26: 46028 | B26: I | C26: 10 | D26: 102 | F26: VENTAS PADRE HIDALGO | I26: 28483 | J26: =J25-H26+I26 -> 193528.19
A27: 46028 | B27: I | C27: 10 | D27: 102 | F27: VENTAS PADRE HIDALGO | I27: 34940 | J27: =J26-H27+I27 -> 228468.19
A28: 46028 | B28: I | C28: 90 | D28: 102 | F28: VTA. YURECUARO | G28: 46026 | I28: 17755 | J28: =J27-H28+I28 -> 246223.19
A29: 46028 | B29: I | C29: 90 | D29: 102 | F29: VTA. YURECUARO | G29: 46025 | I29: 16691 | J29: =J28-H29+I29 -> 262914.19
A30: 46028 | B30: I | C30: 10 | D30: 102 | F30: VENTAS PADRE HIDALGO | I30: 19320 | J30: =J29-H30+I30 -> 282234.19
A31: 46028 | B31: I | C31: 10 | D31: 102 | F31: VENTAS PADRE HIDALGO | I31: 4718 | J31: =J30-H31+I31 -> 286952.19
A32: 46028 | B32: TI | D32: - | F32: TRASPASO DE BB | I32: 700000 | J32: =J31-H32+I32 -> 986952.19
A33: 46028 | B33: TI | D33: - | F33: TRASPASO DE SNTDR | I33: 495000 | J33: =J32-H33+I33 -> 1481952.2
A34: 46028 | B34: TI | D34: - | F34: TRASPASO DE BTE 7744 | I34: 670000 | J34: =J33-H34+I34 -> 2151952.2
A35: 46028 | B35: C | C35: 0 | D35: 510 | E35: 13 | F35: Comercializadora Saramel | H35: 301904.75 | J35: =J34-H35+I35 -> 1850047.4
A36: 46028 | B36: C | C36: 50 | D36: 501 | E36: 14 | F36: Tecnica Mexicana de Alimentacion | H36: 135674.31 | J36: =J35-H36+I36 -> 1714373.1
A37: 46028 | B37: I | C37: 10 | D37: 102 | F37: VENTAS PADRE HIDALGO | I37: 18500 | J37: =J36-H37+I37 -> 1732873.1
A38: 46028 | B38: I | C38: 10 | D38: 102 | F38: VENTAS PADRE HIDALGO | I38: 14688 | J38: =J37-H38+I38 -> 1747561.1
A39: 46029 | B39: G | C39: 72 | D39: 612 | F39: SERV BANCA INTERNET/SERV BCA IN 01-31 | H39: 250 | J39: =J38-H39+I39 -> 1747311.1
A40: 46029 | B40: G | C40: 72 | D40: 612 | F40: SERV BANCA INTERNET/OPS SERV BCA IN 01-31 | H40: 1202.5 | J40: =J39-H40+I40 -> 1746108.6
...

Sheet BBVA 6586
A1: FECHA | B1: M | C1: S | D1: C | E1: # | F1: PROVEEDOR | G1: F VTA | H1: RETIRO | I1: DEPOSITO | J1: SALDO
A2: 46024 | B2: I | C2: 75 | D2: 102 | F2: vta tlmkt canindo alfonso arroyo | I2: 9000 | J2: 157475.6 | K2: =J2+H2-I2 -> 148475.6
A3: 46024 | B3: I | C3: 75 | D3: 102 | F3: vta tlmkt canindo alfonso arroyo | I3: 9000 | J3: =J2-H3+I3 -> 166475.6
A4: 46024 | B4: I | C4: 75 | D4: 102 | F4: vta tlmkt canindo alfonso arroyo | I4: 5000 | J4: =J3-H4+I4 -> 171475.6
A5: 46024 | B5: C | C5: 30 | D5: 510 | E5: 1 | F5: Hersheys Mexico | H5: 146226.19 | J5: =J4-H5+I5 -> 25249.41
A6: 46024 | B6: TE | D6: - | F6: TRASPASO ENTRE CTAS 6721 | H6: 20000 | J6: =J5-H6+I6 -> 5249.41
A7: 46024 | B7: I | C7: 75 | D7: 102 | F7: Vta.Tlmk Canindo Teresa Manzo | G7: 45994 | I7: 22500 | J7: =J6-H7+I7 -> 27749.41
A8: 46024 | B8: I | C8: 75 | D8: 102 | F8: Vta.Tlmk Canindo Teresa Manzo | G8: 45994 | I8: 16200 | J8: =J7-H8+I8 -> 43949.41
A9: 46024 | B9: I | C9: 75 | D9: 102 | F9: Vta.Tlmk Canindo Teresa Manzo | G9: 45994 | I9: 3300 | J9: =J8-H9+I9 -> 47249.41
A10: 46024 | B10: I | C10: 75 | D10: 102 | F10: vta tlmkt canindo alfonso arroyo | I10: 760 | J10: =J9-H10+I10 -> 48009.41
A11: 46027 | B11: I | C11: 75 | D11: 102 | F11: Vta Tlmt Canindo Maria Elena Alvarez | G11: 46020 | I11: 10282.76 | J11: =J10-H11+I11 -> 58292.17
A12: 46027 | B12: I | C12: 75 | D12: 102 | F12: VTA TLMLKT CANINDO MARIA ELENA ALVAREZ | G12: 45992 | I12: 39695.1 | J12: =J11-H12+I12 -> 97987.27
A13: 46028 | B13: I | C13: 75 | D13: 102 | F13: Vta.Tlmk Canindo Victor Hugo | G13: 45996 | I13: 40000 | J13: =J12-H13+I13 -> 137987.27
A14: 46028 | B14: I | C14: 75 | D14: 102 | F14: Vta.Tlmk Canindo Laura Efigenia | G14: 46021 | I14: 51384.85 | J14: =J13-H14+I14 -> 189372.12
A15: 46028 | B15: I | C15: 75 | D15: 102 | F15: Vta.Tlmk Canindo Juan Manuel M | G15: 45997 | I15: 90000 | J15: =J14-H15+I15 -> 279372.12
A16: 46028 | B16: I | C16: 75 | D16: 102 | F16: Vta.Tlmk Canindo Brenda Arredondo | G16: 45989 | I16: 24313 | J16: =J15-H16+I16 -> 303685.12
A17: 46028 | B17: I | C17: 75 | D17: 102 | F17: Vta.Tlmk Canindo Ana Laura | G17: 46009 | I17: 52230 | J17: =J16-H17+I17 -> 355915.12
A18: 46028 | B18: C | C18: 0 | D18: 510 | E18: 2 | F18: Qualamex | H18: 169132.12 | J18: =J17-H18+I18 -> 186783
A19: 46028 | B19: C | C19: 30 | D19: 510 | E19: 3 | F19: Mario Alberto Rodriguez | H19: 56408.4 | J19: =J18-H19+I19 -> 130374.6
A20: 46028 | B20: C | C20: 10 | D20: 510 | E20: 4 | F20: Mario Alberto Rodriguez | H20: 76631.2 | J20: =J19-H20+I20 -> 53743.4
A21: 46029 | B21: I | C21: 75 | D21: 102 | F21: Vta.Tlmk Canindo Manuel Camarena | G21: 46004 | I21: 55576.88 | J21: =J20-H21+I21 -> 109320.28
A22: 46029 | B22: C | C22: 0 | D22: 510 | E22: 5 | F22: Ma Soledad Gutierrez | H22: 64012.03 | J22: =J21-H22+I22 -> 45308.25
A23: 46029 | B23: G | C23: 12 | D23: 610 | E23: 6 | F23: Maria del Carmen Heredia Navarro | H23: 11252 | J23: =J22-H23+I23 -> 34056.25
A24: 46029 | B24: G | C24: 12 | D24: 613 | E24: 7 | F24: America Alejandra Lopez | H24: 29587.5 | J24: =J23-H24+I24 -> 4468.75
A25: 46029 | B25: I | C25: 75 | D25: 102 | F25: Vta.Tlmk Canindo Maria del Rosario | G25: 45996 | I25: 43044.87 | J25: =J24-H25+I25 -> 47513.62
A26: 46030 | B26: I | C26: 75 | D26: 102 | F26: Vta.Tlmk Canindo Dalia Morales | G26: 46003 | I26: 15000 | J26: =J25-H26+I26 -> 62513.62
A27: 46030 | B27: I | C27: 75 | D27: 102 | F27: Vta.Tlmk Canindo Cirenia Margarita | G27: 45982 | I27: 10000 | J27: =J26-H27+I27 -> 72513.62
A28: 46030 | B28: I | C28: 75 | D28: 102 | F28: Vta.Tlmk Canindo Alan Vazquez | G28: 46017 | I28: 21762.5 | J28: =J27-H28+I28 -> 94276.12
A29: 46030 | B29: I | C29: 75 | D29: 102 | F29: Vta.Tlmk Canindo Bernardo Vazquez | G29: 46017 | I29: 39274.5 | J29: =J28-H29+I29 -> 133550.62
A30: 46030 | B30: I | C30: 75 | D30: 102 | F30: Vta.Tlmk Canindo Alan Vazquez | G30: 45996 | I30: 32064 | J30: =J29-H30+I30 -> 165614.62
A31: 46030 | B31: I | C31: 75 | D31: 102 | F31: Vta.Tlmk Canindo Bernardo Vazquez | G31: 46004 | I31: 47424.5 | J31: =J30-H31+I31 -> 213039.12
A32: 46030 | B32: I | C32: 75 | D32: 102 | F32: Vta.Tlmk Canindo Alan Vazquez | G32: 46003 | I32: 39318.5 | J32: =J31-H32+I32 -> 252357.62
A33: 46030 | B33: I | C33: 54 | D33: 102 | F33: VENTA ZAMORA CENTRO | I33: 34710 | J33: =J32-H33+I33 -> 287067.62
A34: 46030 | B34: I | C34: 75 | D34: 102 | F34: Vta.Tlmk Canindo Juan de la Peña | G34: 45982 | I34: 2033 | J34: =J33-H34+I34 -> 289100.62
A35: 46030 | B35: I | D35: 102 | F35: DEV SDO A FAVOR FACT 9949 | I35: 6320.38 | J35: =J34-H35+I35 -> 295421
A36: 46030 | B36: ID | D36: 102 | F36: DEV. JORGE ALBERTO CONTRERAS BAUTISTA MAXIFUM | I36: 32016 | J36: =J35-H36+I36 -> 327437
A37: 46030 | B37: I | C37: 75 | D37: 102 | F37: Vta.Tlmk Canindo Sandra Araceli | G37: 46003 | I37: 120000 | J37: =J36-H37+I37 -> 447437
A38: 46030 | B38: TE | D38: - | F38: TRASPASO ENTRE CTAS 5712 | H38: 440000 | J38: =J37-H38+I38 -> 7437
A39: 46031 | B39: I | D39: 102 | F39: DEV FACTS | I39: 4920 | J39: =J38-H39+I39 -> 12357
A40: 46031 | B40: I | C40: 75 | D40: 102 | F40: Vta.Tlmk Canindo Maria Dolores | G40: 45999 | I40: 140947 | J40: =J39-H40+I40 -> 153304
...

Sheet BBVA 4176
A1: FECHA | B1: M | C1: S | D1: C | E1: # | F1: PROVEEDOR | G1: F VTA | H1: RETIRO | I1: DEPOSITO | J1: SALDO
A2: 46024 | B2: I | C2: 73 | D2: 102 | F2: Vta.Tlmk Morelia Andrea Silva | G2: 46017 | I2: 1403.59 | J2: 4524.65 | K2: =J2+H2-I2 -> 3121.06
A3: 46024 | B3: I | C3: 73 | D3: 102 | F3: Vta.Tlmk Morelia Jose Ma. leyva | G3: 45995 | I3: 30357.54 | J3: =J2-H3+I3 -> 34882.19
A4: 46024 | B4: I | C4: 32 | D4: 102 | F4: VENTAS MORELIA MADERO | G4: 46024 | I4: 1500 | J4: =J3-H4+I4 -> 36382.19
A5: 46024 | B5: TE | D5: - | F5: TRASPASO ENTRE CTAS 6721 | H5: 30000 | J5: =J4-H5+I5 -> 6382.19
A6: 46024 | B6: G | C6: 30 | D6: 610 | E6: 1 | F6: Nom 01 Pension | H6: 735.51 | J6: =J5-H6+I6 -> 5646.68
A7: 46024 | B7: I | C7: 30 | D7: 102 | F7: VENTAS MORELIA ABASTOS | G7: 46030 | I7: 3669.75 | J7: =J6-H7+I7 -> 9316.43
A8: 46024 | B8: I | C8: 30 | D8: 102 | F8: VENTAS MORELIA ABASTOS | G8: 46030 | I8: 4000 | J8: =J7-H8+I8 -> 13316.43
A9: 46026 | B9: I | C9: 30 | D9: 102 | F9: VENTAS MORELIA ABASTOS | G9: 46030 | I9: 6287.63 | J9: =J8-H9+I9 -> 19604.06
A10: 46027 | B10: I | C10: 73 | D10: 102 | F10: Vta.Tlmk Morelia Norma Isela | G10: 46014 | I10: 2656 | J10: =J9-H10+I10 -> 22260.06
A11: 46027 | B11: I | C11: 73 | D11: 102 | F11: Vta.Tlmk Morelia Manuel Alejandro | G11: 46011 | I11: 8797.05 | J11: =J10-H11+I11 -> 31057.11
A12: 46027 | B12: I | C12: 73 | D12: 102 | F12: Vta.Tlmk Morelia Maria Domitila | G12: 46000 | I12: 62753.63 | J12: =J11-H12+I12 -> 93810.74
A13: 46027 | B13: I | C13: 73 | D13: 102 | F13: Vta.Tlmk Morelia Maria Domitila | G13: 46007 | I13: 29394.98 | J13: =J12-H13+I13 -> 123205.72
A14: 46028 | B14: G | C14: 12 | D14: 613 | E14: 2 | F14: Juan Manuel Espinoza | H14: 2450 | J14: =J13-H14+I14 -> 120755.72
A15: 46028 | B15: I | C15: 73 | D15: 102 | F15: Vta.Tlmk Morelia Paola Lopez | G15: 46001 | I15: 44507 | J15: =J14-H15+I15 -> 165262.72
A16: 46028 | B16: C | C16: 10 | D16: 510 | E16: 3 | F16: Miguel Angel Bribiesca | H16: 11901.6 | J16: =J15-H16+I16 -> 153361.12
A17: 46028 | B17: C | C17: 30 | D17: 510 | E17: 4 | F17: Vidis SA de CV | H17: 84600.28 | J17: =J16-H17+I17 -> 68760.84
A18: 46028 | B18: I | C18: 73 | D18: 102 | F18: Vta.Tlmk Morelia Seferina Garcia | G18: 46025 | I18: 3938 | J18: =J17-H18+I18 -> 72698.84
A19: 46028 | B19: I | C19: 73 | D19: 102 | F19: Vta.Tlmk Morelia Seferina Garcia | G19: 46018 | I19: 2333 | J19: =J18-H19+I19 -> 75031.84
A20: 46028 | B20: I | C20: 32 | D20: 102 | F20: VENTAS MORELIA MADERO | G20: 46028 | I20: 2299.37 | J20: =J19-H20+I20 -> 77331.21
A21: 46029 | B21: I | C21: 30 | D21: 102 | F21: VENTAS MORELIA ABASTOS | G21: 46031 | I21: 3600 | J21: =J20-H21+I21 -> 80931.21
A22: 46029 | B22: C | C22: 50 | D22: 510 | E22: 5 | F22: Botanas y Cereales de Zamora | H22: 52278.97 | J22: =J21-H22+I22 -> 28652.24
A23: 46029 | B23: G | C23: 30 | D23: 613 | E23: 6 | F23: FONACOT | H23: 6812.74 | J23: =J22-H23+I23 -> 21839.5
A24: 46029 | B24: G | C24: 90 | D24: 610 | E24: 7 | F24: Ma Eugenia Campos Moya | H24: 17400 | J24: =J23-H24+I24 -> 4439.5
A25: 46030 | B25: I | C25: 73 | D25: 102 | F25: Vta.Tlmk Morelia Rosario Morales | G25: 46013 | I25: 31232.5 | J25: =J24-H25+I25 -> 35672
A26: 46030 | B26: I | C26: 73 | D26: 102 | F26: Vta.Tlmk Morelia Francisco Garcia | G26: 46011 | I26: 11159.25 | J26: =J25-H26+I26 -> 46831.25
A27: 46030 | B27: I | C27: 73 | D27: 102 | F27: Vta.Tlmk Morelia Leonel Silva | G27: 46024 | I27: 24868.36 | J27: =J26-H27+I27 -> 71699.61
A28: 46030 | B28: I | C28: 73 | D28: 102 | F28: Vta.Tlmk Morelia Leonel Silva | G28: 46024 | I28: 27516.6 | J28: =J27-H28+I28 -> 99216.21
A29: 46030 | B29: I | C29: 73 | D29: 102 | F29: Vta.Tlmk Morelia Jesus Sanchez | G29: 46020 | I29: 11526 | J29: =J28-H29+I29 -> 110742.21
A30: 46030 | B30: I | C30: 30 | D30: 102 | F30: VENTAS MORELIA ABASTOS | G30: 46030 | I30: 12644 | J30: =J29-H30+I30 -> 123386.21
A31: 46030 | B31: I | C31: 73 | D31: 102 | F31: Vta.Tlmk Morelia Jesus Sanchez | G31: 46013 | I31: 8807 | J31: =J30-H31+I31 -> 132193.21
A32: 46030 | B32: TI | D32: - | F32: TRASPASO ENTRE CTAS 6721 | I32: 60000 | J32: =J31-H32+I32 -> 192193.21
A33: 46030 | B33: C | D33: 510 | E33: 8 | F33: Cuetara Distribuciones | H33: 14254.43 | J33: =J32-H33+I33 -> 177938.78
A34: 46030 | B34: S | F34: Spei Cuetara | H34: 128000 | J34: =J33-H34+I34 -> 49938.78
A35: 46030 | B35: DS | F35: Dev Spei Cuetara | I35: 128000 | J35: =J34-H35+I35 -> 177938.78
A36: 46031 | B36: S | F36: Spei Cuetara | H36: 128000 | J36: =J35-H36+I36 -> 49938.78
A37: 46031 | B37: DS | F37: Dev Spei Cuetara | I37: 128000 | J37: =J36-H37+I37 -> 177938.78
A38: 46031 | B38: I | C38: 73 | D38: 102 | F38: Vta.Tlmk Morelia Crisanto Bautista | G38: 46031 | I38: 20486.81 | J38: =J37-H38+I38 -> 198425.59
A39: 46031 | B39: G | C39: 30 | D39: 610 | E39: 9 | F39: Nom 02 pension | H39: 882.62 | J39: =J38-H39+I39 -> 197542.97
A40: 46031 | B40: C | C40: 30 | D40: 510 | E40: 10 | F40: Abarrotes La Violeta | H40: 86827.03 | J40: =J39-H40+I40 -> 110715.94
...

Sheet BBVA 4885
A1: FECHA | B1: M | C1: S | D1: C | E1: # | F1: PROVEEDOR | G1: F VTA | H1: RETIRO | I1: DEPOSITO | J1: SALDO
A2: 46050 | B2: C | D2: 510 | E2: 1 | F2: DIF FACT LA GRANJA ORGANICA | H2: 290 | J2: 401.48 | K2: =J2+H2-I2 -> 691.48

Sheet BBVA 6721
A1: FECHA | B1: M | C1: S | D1: C | E1: # | F1: PROVEEDOR | G1: F VTA | H1: RETIRO | I1: DEPOSITO | J1: SALDO
A2: 46023 | B2: I | C2: 70 | D2: 102 | F2: Vta.Tlmk Ph Ma. Magdalena | G2: 45994 | I2: 92015.01 | J2: 95486.57 | K2: =J2+H2-I2 -> 3471.56
A3: 46023 | B3: I | C3: 73 | D3: 102 | F3: Vta.Tlmk Morelia Juan Jose Camacho | G3: 46021 | I3: 3600 | J3: =J2-H3+I3 -> 99086.57
A4: 46023 | B4: I | C4: 73 | D4: 102 | F4: Vta.Tlmk Morelia Juan Jose Camacho | G4: 46021 | I4: 1000 | J4: =J3-H4+I4 -> 100086.57
A5: 46024 | B5: I | C5: 70 | D5: 102 | F5: Vta.Tlmk Ph Diego Maestro | G5: 46000 | I5: 11248.84 | J5: =J4-H5+I5 -> 111335.41
A6: 46024 | B6: I | C6: 70 | D6: 102 | F6: Vta.Tlmk Ph Anahi Elizabeth | G6: 46002 | I6: 8000 | J6: =J5-H6+I6 -> 119335.41
A7: 46024 | B7: I | C7: 70 | D7: 102 | F7: Vta.Tlmk Ph Anahi Elizabeth | G7: 46002 | I7: 4414 | J7: =J6-H7+I7 -> 123749.41
A8: 46024 | B8: I | C8: 73 | D8: 102 | F8: Vta.Tlmk Morelia Ma. Maricela | G8: 46015 | I8: 7128.63 | J8: =J7-H8+I8 -> 130878.04
A9: 46024 | B9: I | C9: 70 | D9: 102 | F9: Vta.Tlmk Ph Luis Alberto Estrada | G9: 46008 | I9: 30097.18 | J9: =J8-H9+I9 -> 160975.22
A10: 46024 | B10: I | C10: 73 | D10: 102 | F10: Vta.Tlmk Morelia Oscas torres | G10: 45995 | I10: 15000 | J10: =J9-H10+I10 -> 175975.22
A11: 46024 | B11: I | C11: 73 | D11: 102 | F11: Vta.Tlmk Morelia Maribel Angel | G11: 46020 | I11: 18534.9 | J11: =J10-H11+I11 -> 194510.12
A12: 46024 | B12: I | C12: 73 | D12: 102 | F12: Vta.Tlmk Morelia Ruben Gomez | G12: 46007 | I12: 27511 | J12: =J11-H12+I12 -> 222021.12
A13: 46024 | B13: I | C13: 73 | D13: 102 | F13: Vta.Tlmk Morelia Martin suarez | G13: 45988 | I13: 80000 | J13: =J12-H13+I13 -> 302021.12
A14: 46024 | B14: I | C14: 73 | D14: 102 | F14: Vta.Tlmk Morelia Ruben Gomez | G14: 46013 | I14: 48828.9 | J14: =J13-H14+I14 -> 350850.02
A15: 46024 | B15: C | C15: 0 | D15: 510 | E15: 1 | F15: Dulceria de los Altos | H15: 257467.47 | J15: =J14-H15+I15 -> 93382.55
A16: 46024 | B16: TI | D16: - | F16: TRASPASO ENTRE CTAS 4176 | I16: 30000 | J16: =J15-H16+I16 -> 123382.55
A17: 46024 | B17: TI | D17: - | F17: TRASPASO ENTRE CTAS 6586 | I17: 20000 | J17: =J16-H17+I17 -> 143382.55
A18: 46024 | B18: C | C18: 10 | D18: 510 | E18: 2 | F18: Distribuidora de la Rosa SA de Cv | H18: 135438.42 | J18: =J17-H18+I18 -> 7944.13
A19: 46024 | B19: I | C19: 70 | D19: 102 | F19: Vta.Tlmk Ph Gloria Hernandez | G19: 46000 | I19: 6000 | J19: =J18-H19+I19 -> 13944.13
A20: 46024 | B20: I | C20: 70 | D20: 102 | F20: Vta.Tlmk Ph Gloria Hernandez | G20: 46000 | I20: 6000 | J20: =J19-H20+I20 -> 19944.13
A21: 46026 | B21: I | D21: 102 | F21: Dep. Efectivo | I21: 1500 | J21: =J20-H21+I21 -> 21444.13
A22: 46027 | B22: I | C22: 73 | D22: 102 | F22: Vta.Tlmk Morelia Ma. Maricela | G22: 46010 | I22: 19728.7 | J22: =J21-H22+I22 -> 41172.83
A23: 46027 | B23: I | C23: 70 | D23: 102 | F23: Vta.Tlmk Ph Dulceria de los altos | G23: 46024 | I23: 21210.01 | J23: =J22-H23+I23 -> 62382.84
A24: 46027 | B24: I | C24: 70 | D24: 102 | F24: Vta.Tlmk Ph Maria Guadalupe R | G24: 45995 | I24: 20000 | J24: =J23-H24+I24 -> 82382.84
A25: 46027 | B25: I | C25: 73 | D25: 102 | F25: Vta.Tlmk Morelia Maria d Lourdes | G25: 46004 | I25: 12811.86 | J25: =J24-H25+I25 -> 95194.7
A26: 46027 | B26: I | C26: 73 | D26: 102 | F26: Vta.Tlmk Morelia Maria d Lourdes | G26: 46021 | I26: 37921.74 | J26: =J25-H26+I26 -> 133116.44
A27: 46028 | B27: I | C27: 73 | D27: 102 | F27: Vta.Tlmk Morelia Marcelo Sandoval | G27: 46010 | I27: 60000 | J27: =J26-H27+I27 -> 193116.44
A28: 46028 | B28: I | C28: 73 | D28: 102 | F28: Vta.Tlmk Morelia Mayela Guevara | G28: 46009 | I28: 25353.44 | J28: =J27-H28+I28 -> 218469.88
A29: 46028 | B29: I | C29: 73 | D29: 102 | F29: Vta.Tlmk Morelia Oscas torres | G29: 45995 | I29: 13486.95 | J29: =J28-H29+I29 -> 231956.83
A30: 46028 | B30: I | C30: 73 | D30: 102 | F30: Vta.Tlmk Morelia Mayela Guevara | G30: 46002 | I30: 33116.83 | J30: =J29-H30+I30 -> 265073.66
A31: 46028 | B31: I | C31: 73 | D31: 102 | F31: Vta.Tlmk Morelia Mayela Guevara | G31: 46009 | I31: 1556.48 | J31: =J30-H31+I31 -> 266630.14
A32: 46028 | B32: I | C32: 73 | D32: 102 | F32: Vta.Tlmk Morelia oscas torres | G32: 45995 | I32: 5759 | J32: =J31-H32+I32 -> 272389.14
A33: 46028 | B33: I | C33: 73 | D33: 102 | F33: Vta.Tlmk Morelia Mayela Guevara | G33: 46002 | I33: 5000 | J33: =J32-H33+I33 -> 277389.14
... A40: 46028 | B40: I | C40: 70 | D40: 102 | F40: Vta.Tlmk Ph Gloria Hernandez | G40: 46000 | I40: 10000 | J40: =J39-H40+I40 -> 427031.57
A41: 46028 | B41: C | C41: 0 | D41: 510 | E41: 3 | F41: Dulfree Comercial | H41: 391176.16 | J41: =J40-H41+I41 -> 35855.41
A42: 46028 | B42: I | C42: 70 | D42: 102 | F42: Vta.Tlmk Ph Gloria Hernandez | G42: 46000 | I42: 10000 | J42: =J41-H42+I42 -> 45855.41
A43: 46028 | B43: C | C43: 0 | D43: 510 | E43: 4 | F43: Picao alimentos | H43: 31370.06 | J43: =J42-H43+I43 -> 14485.35
A44: 46028 | B44: I | C44: 70 | D44: 102 | F44: Vta.Tlmk Ph Gloria Hernandez | G44: 46000 | I44: 6000 | J44: =J43-H44+I44 -> 20485.35
A45: 46028 | B45: I | C45: 73 | D45: 102 | F45: Vta.Tlmk Morelia Patricia Paredes | G45: 46011 | I45: 10400 | J45: =J44-H45+I45 -> 30885.35
A46: 46029 | B46: I | C46: 70 | D46: 102 | F46: Vta.Tlmk Ph Anahi Elizabeth | G46: 46017 | I46: 9000 | J46: =J45-H46+I46 -> 39885.35
...

Sheet BBVA 2182
A1: FECHA | B1: M | C1: S | D1: C | E1: # | F1: PROVEEDOR | G1: F VTA | H1: RETIRO | I1: DEPOSITO | J1: SALDO
A2: 46024 | B2: G | C2: 72 | D2: 612 | F2: PENALIZACION SDO PROM MIN | H2: 420 | J2: 92.8 | K2: =J2+H2-I2 -> 512.8
A3: 46024 | B3: G | C3: 72 | D3: 147 | F3: IVA | H3: 67.2 | J3: =J2-H3+I3 -> 25.6

Sheet BB 4166
A1: FECHA | B1: M | C1: S | D1: C | E1: # | F1: PROVEEDOR | G1: F VTA | H1: RETIRO | I1: DEPOSITO | J1: SALDO
A2: 46023 | B2: G | D2: 613 | F2: Compra - Disposicion por POS por (602.45) mxn en SERV TAVISA GASOL 31dic2025 RFC EST 161221BS3 Tarjeta 5161020004397545 Recibo # 4394923032322 | H2: 602.45 | J2: 136786.88 | K2: =J2+H2-I2 -> 137389.33
A3: 46023 | B3: G | D3: 613 | F3: Compra - Disposicion por POS por (463.00) mxn en PZA COBRO PANINDICUARO 31dic2025 RFC HMI 950125KG8 Tarjeta 5161020003551118 Recibo # 4394924032322 | H3: 463 | J3: =J2-H3+I3 -> 136323.88
A4: 46023 | B4: G | D4: 613 | F4: Compra - Disposicion por POS por (463.00) mxn en PZA COBRO PANINDICUARO 31dic2025 RFC HMI 950125KG8 Tarjeta 5161020003551118 Recibo # 4394924032322 | H4: 463 | J4: =J3-H4+I4 -> 135860.88
A5: 46023 | B5: G | D5: 613 | F5: Compra - Disposicion por POS por (1,000.00) mxn en LA QUEMADA GAS 31dic2025 RFC SQU 060616TQ1 Tarjeta 5161020003551084 Recibo # 4394926032322 | H5: 1000 | J5: =J4-H5+I5 -> 134860.88
A6: 46023 | B6: G | D6: 613 | F6: Compra - Disposicion por POS por (3,478.60) mxn en GASOL DEL VALLE 31dic2025 RFC GVZ 970421PJ7 Tarjeta 5161020003411909 Recibo # 4394927032322 | H6: 3478.6 | J6: =J5-H6+I6 -> 131382.28
A7: 46023 | B7: G | D7: 613 | F7: Compra - Disposicion por POS por (1,314.20) mxn en SUPER SERV GARBRI 31dic2025 RFC SSG 981118LR6 Tarjeta 5161020003551126 Recibo # 4394928032322 | H7: 1314.2 | J7: =J6-H7+I7 -> 130068.08
A8: 46023 | B8: G | D8: 613 | F8: Compra - Disposicion por POS por (1,568.80) mxn en SUPER SERV GARBRI 31dic2025 RFC SSG 981118LR6 Tarjeta 5161020003551126 Recibo # 4394929032322 | H8: 1568.8 | J8: =J7-H8+I8 -> 128499.28
A9: 46023 | B9: G | D9: 613 | F9: Compra - Disposicion por POS por (751.53) mxn en SUPER SERV GARBRI 31dic2025 RFC SSG 981118LR6 Tarjeta 5161020003884857 Recibo # 4394930032322 | H9: 751.53 | J9: =J8-H9+I9 -> 127747.75
A10: 46023 | B10: G | D10: 613 | F10: Compra - Disposicion por POS por (746.02) mxn en SUPER SERV GARBRI 31dic2025 RFC SSG 981118LR6 Tarjeta 5161020003884857 Recibo # 4394931032322 | H10: 746.02 | J10: =J9-H10+I10 -> 127001.73
A11: 46023 | B11: G | D11: 613 | F11: Compra - Disposicion por POS por (1,486.63) mxn en SUPER SERV GARBRI 31dic2025 RFC SSG 981118LR6 Tarjeta 5161020003551118 Recibo # 4394932032322 | H11: 1486.63 | J11: =J10-H11+I11 -> 125515.1
A12: 46023 | B12: G | D12: 613 | F12: Compra - Disposicion por POS por (379.93) mxn en LA QUEMADA GAS 31dic2025 RFC SQU 060616TQ1 Tarjeta 5161020003551084 Recibo # 4394933032322 | H12: 379.93 | J12: =J11-H12+I12 -> 125135.17
A13: 46024 | B13: G | D13: 613 | F13: Compra - Disposicion por POS por (3,161.18) mxn en SUPER SERV GARBRI 01ene2026 RFC SSG 981118LR6 Tarjeta 5161020003884857 Recibo # 4412406032322 | H13: 3161.18 | J13: =J12-H13+I13 -> 121973.99
A14: 46024 | B14: G | D14: 613 | F14: Compra - Disposicion por POS por (3,308.94) mxn en SUPER SERV GARBRI 01ene2026 RFC SSG 981118LR6 Tarjeta 5161020003551118 Recibo # 4412407032322 | H14: 3308.94 | J14: =J13-H14+I14 -> 118665.05
A15: 46024 | B15: I | C15: 51 | D15: 102 | F15: VENTAS RD CANINDO | G15: 46022 | I15: 10049.96 | J15: =J14-H15+I15 -> 128715.01
A16: 46024 | B16: I | C16: 51 | D16: 102 | F16: VENTAS RD CANINDO | G16: 46022 | I16: 10128.03 | J16: =J15-H16+I16 -> 138843.04
A17: 46024 | B17: I | C17: 51 | D17: 102 | F17: VENTAS RD CANINDO | G17: 46022 | I17: 14933.53 | J17: =J16-H17+I17 -> 153776.57
A18: 46024 | B18: I | C18: 51 | D18: 102 | F18: VENTAS RD CANINDO | G18: 46022 | I18: 9146.72 | J18: =J17-H18+I18 -> 162923.29
A19: 46024 | B19: G | D19: 610 | E19: 1 | F19: Nomina 01 | H19: 10613.6 | J19: =J18-H19+I19 -> 152309.69
A20: 46024 | B20: G | D20: 610 | E20: 2 | F20: Nomina 01 | H20: 7766.4 | J20: =J19-H20+I20 -> 144543.29
A21: 46024 | B21: TE | D21: - | F21: TRASPASO A BTE 7744 | H21: 100000 | J21: =J20-H21+I21 -> 44543.29
A22: 46024 | B22: G | D22: 612 | F22: Comision | H22: 0 | J22: =J21-H22+I22 -> 44543.29
A23: 46024 | B23: G | D23: 147 | F23: Iva | H23: 0 | J23: =J22-H23+I23 -> 44543.29
A24: 46024 | B24: TI | D24: - | F24: TRASPASO ENTRE CTAS 854 | I24: 50000 | J24: =J23-H24+I24 -> 94543.29
A25: 46024 | B25: G | D25: 610 | E25: 3 | F25: Nomina 01 | H25: 3884.6 | J25: =J24-H25+I25 -> 90658.69
A26: 46024 | B26: G | D26: 610 | E26: 4 | F26: Nomina 01 | H26: 6281.2 | J26: =J25-H26+I26 -> 84377.49
A27: 46024 | B27: TI | D27: - | F27: TRASPASO ENTRE CTAS 366 | I27: 35000 | J27: =J26-H27+I27 -> 119377.49
A28: 46024 | B28: TI | D28: - | F28: TRASPASO DE SNTDR 2169 | I28: 450000 | J28: =J27-H28+I28 -> 569377.49
A29: 46024 | B29: TI | D29: - | F29: TRASPASO DE SNTDR 1604 | I29: 430000 | J29: =J28-H29+I29 -> 999377.49
A30: 46025 | B30: G | C30: 72 | D30: 612 | F30: Administración de Tarjeta Adicional | H30: 200 | J30: =J29-H30+I30 -> 999177.49
A31: 46025 | B31: G | C31: 72 | D31: 147 | F31: IVA | H31: 32 | J31: =J30-H31+I31 -> 999145.49
A32: 46025 | B32: G | D32: 613 | F32: Compra - Disposicion por POS por (500.00) mxn en SERV TAVISA GASOL02ene2026 RFC EST 161221BS3 Tarjeta 5161020004397552 Recibo # 4432659032322 | H32: 500 | J32: =J31-H32+I32 -> 998645.49
A33: 46025 | B33: G | D33: 613 | F33: Compra - Disposicion por POS por (699.12) mxn en GASOL DEL VALLE 02ene2026 RFC GVZ 970421PJ7 Tarjeta 5161020003411883 Recibo # 4432660032322 | H33: 699.12 | J33: =J32-H33+I33 -> 997946.37
A34: 46025 | B34: G | D34: 613 | F34: Compra - Disposicion por POS por (2,480.93) mxn en GASOL DEL VALLE 02ene2026 RFC GVZ 970421PJ7 Tarjeta 5161020004397602 Recibo # 4432661032322 | H34: 2480.93 | J34: =J33-H34+I34 -> 995465.44
A35: 46025 | B35: G | D35: 613 | F35: Compra - Disposicion por POS por (1,144.03) mxn en SERV TAVISA GASOL 02ene2026 RFC EST 161221BS3 Tarjeta 5161020004397537 Recibo # 4432662032322 | H35: 1144.03 | J35: =J34-H35+I35 -> 994321.41
A36: 46025 | B36: G | D36: 613 | F36: Compra - Disposicion por POS por (1,420.87) mxn en SERV TAVISA GASOL 02ene2026 RFC EST 161221BS3 Tarjeta 5161020004397560 Recibo # 4432663032322 | H36: 1420.87 | J36: =J35-H36+I36 -> 992900.54
A37: 46025 | B37: G | D37: 613 | F37: Compra - Disposicion por POS por (730.03) mxn en SERV NORAMA 02ene2026 RFC SNO 971210G06 Tarjeta 5161020003411909 Recibo # 4432664032322 | H37: 730.03 | J37: =J36-H37+I37 -> 992170.51
A38: 46025 | B38: G | D38: 613 | F38: Compra - Disposicion por POS por (445.32) mxn en DIST GAS NOEL 02ene2026 RFC DGN 811026BU6 Tarjeta 5161020003551118 Recibo # 4432665032322 | H38: 445.32 | J38: =J37-H38+I38 -> 991725.19
A39: 46025 | B39: G | D39: 613 | F39: Compra - Disposicion por POS por (1,504.28) mxn en SERV TAVISA GASOL 02ene2026 RFC EST 161221BS3 Tarjeta 5161020004397560 Recibo # 4432666032322 | H39: 1504.28 | J39: =J38-H39+I39 -> 990220.91
A40: 46025 | B40: G | D40: 613 | F40: Compra - Disposicion por POS por (1,157.81) mxn en GASOL DEL VALLE 02ene2026 RFC GVZ 970421PJ7 Tarjeta 5161020004397636 Recibo # 4432667032322 | H40: 1157.81 | J40: =J39-H40+I40 -> 989063.1
...

Sheet BB 854
A1: FECHA | B1: M | C1: S | D1: C | E1: # | F1: PROVEEDOR | G1: F VTA | H1: RETIRO | I1: DEPOSITO | J1: SALDO
A2: 46023 | B2: I | C2: 54 | D2: 102 | F2: venta zamora centro tarjeta | G2: 46022 | I2: 4445.59 | J2: 4987.04 | K2: =J2+H2-I2 -> 541.45
A3: 46023 | B3: G | D3: 612 | F3: Comision | H3: 71.11 | J3: =J2-H3+I3 -> 4915.93
A4: 46023 | B4: G | D4: 147 | F4: Iva | H4: 11.38 | J4: =J3-H4+I4 -> 4904.55
A5: 46023 | B5: I | C5: 54 | D5: 102 | F5: venta zamora centro tarjeta | G5: 46022 | I5: 6053.79 | J5: =J4-H5+I5 -> 10958.34
A6: 46023 | B6: G | D6: 612 | F6: Comision | H6: 115.03 | J6: =J5-H6+I6 -> 10843.31
A7: 46023 | B7: G | D7: 147 | F7: Iva | H7: 18.4 | J7: =J6-H7+I7 -> 10824.91
A8: 46024 | B8: I | C8: 54 | D8: 102 | F8: venta zamora centro | G8: 46022 | I8: 39415 | J8: =J7-H8+I8 -> 50239.91
A9: 46024 | B9: TE | D9: - | F9: TRASPASO ENTRE CTAS 4166 | H9: 50000 | J9: =J8-H9+I9 -> 239.91
A10: 46025 | B10: I | C10: 54 | D10: 102 | F10: venta zamora centro tarjeta | G10: 46024 | I10: 1282.81 | J10: =J9-H10+I10 -> 1522.72
A11: 46025 | B11: G | D11: 612 | F11: Comision | H11: 20.52 | J11: =J10-H11+I11 -> 1502.2
A12: 46025 | B12: G | D12: 147 | F12: Iva | H12: 3.28 | J12: =J11-H12+I12 -> 1498.92
A13: 46025 | B13: I | C13: 54 | D13: 102 | F13: venta zamora centro tarjeta | G13: 46024 | I13: 1232.08 | J13: =J12-H13+I13 -> 2731
A14: 46025 | B14: G | D14: 612 | F14: Comision | H14: 23.41 | J14: =J13-H14+I14 -> 2707.59
A15: 46025 | B15: G | D15: 147 | F15: Iva | H15: 3.75 | J15: =J14-H15+I15 -> 2703.84
A16: 46026 | B16: I | C16: 54 | D16: 102 | F16: venta zamora centro tarjeta | G16: 46025 | I16: 2844.87 | J16: =J15-H16+I16 -> 5548.71
A17: 46026 | B17: G | D17: 612 | F17: Comision | H17: 54.06 | J17: =J16-H17+I17 -> 5494.65
A18: 46026 | B18: G | D18: 147 | F18: Iva | H18: 8.65 | J18: =J17-H18+I18 -> 5486
A19: 46026 | B19: I | C19: 54 | D19: 102 | F19: venta zamora centro tarjeta | G19: 46025 | I19: 894.84 | J19: =J18-H19+I19 -> 6380.84
A20: 46026 | B20: G | D20: 612 | F20: Comision | H20: 14.31 | J20: =J19-H20+I20 -> 6366.53
A21: 46026 | B21: G | D21: 147 | F21: Iva | H21: 2.29 | J21: =J20-H21+I21 -> 6364.24
A22: 46027 | B22: I | C22: 54 | D22: 102 | F22: venta zamora centro tarjeta | G22: 46026 | I22: 1479.25 | J22: =J21-H22+I22 -> 7843.49
A23: 46027 | B23: G | D23: 612 | F23: Comision | H23: 23.67 | J23: =J22-H23+I23 -> 7819.82
A24: 46027 | B24: G | D24: 147 | F24: Iva | H24: 3.79 | J24: =J23-H24+I24 -> 7816.03
A25: 46027 | B25: I | C25: 54 | D25: 102 | F25: venta zamora centro | G25: 46026 | I25: 1032.31 | J25: =J24-H25+I25 -> 8848.34
A26: 46027 | B26: G | D26: 612 | F26: Comision | H26: 19.62 | J26: =J25-H26+I26 -> 8828.72
A27: 46027 | B27: G | D27: 147 | F27: Iva | H27: 3.14 | J27: =J26-H27+I27 -> 8825.58
A28: 46027 | B28: I | C28: 54 | D28: 102 | F28: venta zamora centro | G28: 46024 | I28: 37178.5 | J28: =J27-H28+I28 -> 46004.08
A29: 46027 | B29: I | C29: 54 | D29: 102 | F29: venta zamora centro | G29: 46025 | I29: 46778 | J29: =J28-H29+I29 -> 92782.08
A30: 46027 | B30: I | C30: 54 | D30: 102 | F30: vemta zamora centro | G30: 46026 | I30: 39030 | J30: =J29-H30+I30 -> 131812.08
A31: 46027 | B31: I | C31: 50 | D31: 102 | F31: VENTAS CANINDO | G31: 46032 | I31: 350 | J31: =J30-H31+I31 -> 132162.08
A32: 46027 | B32: I | C32: 50 | D32: 102 | F32: VENTAS CANINDO | G32: 46029 | I32: 5823.5 | J32: =J31-H32+I32 -> 137985.58
A33: 46027 | B33: I | C33: 50 | D33: 102 | F33: VENTAS CANINDO | G33: 46029 | I33: 2967.5 | J33: =J32-H33+I33 -> 140953.08
A34: 46027 | B34: I | C34: 50 | D34: 102 | F34: VENTAS CANINDO | G34: 46029 | I34: 1631.5 | J34: =J33-H34+I34 -> 142584.58
A35: 46027 | B35: I | C35: 50 | D35: 102 | F35: VENTAS CANINDO | G35: 46029 | I35: 526.5 | J35: =J34-H35+I35 -> 143111.08
A36: 46027 | B36: I | C36: 54 | D36: 102 | F36: VENTA ZAMORA CENTRO | I36: 6729.5 | J36: =J35-H36+I36 -> 149840.58
A37: 46027 | B37: TE | D37: - | F37: TRASPASO ENTRE CUENTAS DE BB 201 | H37: 145000 | J37: =J36-H37+I37 -> 4840.58
A38: 46028 | B38: I | C38: 54 | D38: 102 | F38: venta zamora centro tarjeta | G38: 46027 | I38: 3508.23 | J38: =J37-H38+I38 -> 8348.81
A39: 46028 | B39: G | D39: 612 | F39: Comision | H39: 56.13 | J39: =J38-H39+I39 -> 8292.68
